<?xml version="1.0" encoding="utf-8"?>
<!-- This URDF was automatically created by SolidWorks to URDF Exporter! Originally created by Stephen Brawner (brawner@gmail.com) 
     Commit Version: 1.6.0-4-g7f85cfe  Build Version: 1.6.7995.38578
     For more information, please see http://wiki.ros.org/sw_urdf_exporter -->
<robot
        name="biped">
    <material name="black">
        <color rgba="0.0 0.0 0.0 1.0"/>
    </material>
    <material name="blue">
        <color rgba="0.0 0.0 0.8 1.0"/>
    </material>
    <material name="green">
        <color rgba="0.0 0.8 0.0 1.0"/>
    </material>
    <material name="grey">
        <color rgba="0.2 0.2 0.2 1.0"/>
    </material>
    <material name="silver">
        <color rgba="0.9137254901960784 0.9137254901960784 0.8470588235294118 1.0"/>
    </material>
    <material name="orange">
        <color rgba="1.0 0.4235294117647059 0.0392156862745098 1.0"/>
    </material>
    <material name="brown">
        <color rgba="0.8705882352941177 0.8117647058823529 0.7647058823529411 1.0"/>
    </material>
    <material name="red">
        <color rgba="0.8 0.0 0.0 1.0"/>
    </material>
    <material name="white">
        <color rgba="1.0 1.0 1.0 1.0"/>
    </material>
    <!-- ros_control plugin -->
    <gazebo>
        <plugin filename="liblegged_hw_sim.so" name="gazebo_ros_control">
            <robotNamespace>/</robotNamespace>
            <robotParam>legged_robot_description</robotParam>
            <robotSimType>legged_gazebo/LeggedHWSim</robotSimType>
        </plugin>
    </gazebo>
    <gazebo>
        <plugin filename="libgazebo_ros_p3d.so" name="p3d_base_controller">
            <alwaysOn>true</alwaysOn>
            <updateRate>1000.0</updateRate>
            <bodyName>base</bodyName>
            <topicName>ground_truth/state</topicName>
            <gaussianNoise>0</gaussianNoise>
            <frameName>world</frameName>
            <xyzOffsets>0 0 0</xyzOffsets>
            <rpyOffsets>0 0 0</rpyOffsets>
        </plugin>
    </gazebo>
    <link
            name="base">
        <inertial>
            <origin
                    xyz="-0.02117014 0.00034639 0.00300161"
                    rpy="0 0 0"/>
            <mass
                    value="5.65937068"/>
            <inertia
                    ixx="0.07000931"
                    ixy="0.00043103"
                    ixz="0.01804734"
                    iyy="0.05662892"
                    iyz="-0.00001883"
                    izz="0.06306006"/>
        </inertial>
        <visual>
            <origin
                    xyz="0 0 0"
                    rpy="0 0 0"/>
            <geometry>
                <mesh
                        filename="package://legged_rl_description/meshes/biped/base_link.STL"/>
            </geometry>
            <material
                    name="">
                <color
                        rgba="1 1 1 1"/>
            </material>
        </visual>
        <collision>
            <origin
                    xyz="0 0 0"
                    rpy="0 0 0"/>
            <geometry>
                <mesh
                        filename="package://legged_rl_description/meshes/biped/base_link.STL"/>
            </geometry>
        </collision>
    </link>
    <joint name="unitree_imu_joint" type="fixed">
        <origin rpy="0. 0. 0." xyz="0. 0. 0."/>
        <parent link="base"/>
        <child link="unitree_imu"/>
    </joint>
    <!-- Imu link -->
    <link name="unitree_imu">
        <inertial>
            <mass value="0.01"/>
            <origin rpy="0 0 0" xyz="0 0 0"/>
            <inertia ixx="0.000001" ixy="0" ixz="0" iyy="0.000001" iyz="0" izz="0.000001"/>
        </inertial>
        <visual>
            <origin rpy="0 0 0" xyz="0 0 0"/>
            <geometry>
                <box size="0.015 0.015 0.004"/>
            </geometry>
        </visual>
        <material name="orange">
            <color rgba="255 108 10 255"/>
        </material>
    </link>
    <gazebo reference="unitree_imu">
        <material>Gazebo/Orange</material>
    </gazebo>
    <gazebo reference="unitree_imu_joint">
        <disableFixedJointLumping>true</disableFixedJointLumping>
    </gazebo>
    <link name="camera_box">
        <visual>
            <origin rpy="0 0.69813 0" xyz="0.10 0 -0.10"/>
            <geometry>
                <box size="0.025 0.09 0.025"/>
            </geometry>
            <material name="red"/>
        </visual>
    </link>
    <joint name="fixed_camera_box" type="fixed">
        <origin rpy="0 0 0" xyz="0 0 0"/>
        <parent link="base"/>
        <child link="camera_box"/>
    </joint>
    <link
            name="abad_L_Link">
        <inertial>
            <origin
                    xyz="-0.07010163 0.04726369 0.00010664"
                    rpy="0 0 0"/>
            <mass
                    value="1.03648983"/>
            <inertia
                    ixx="0.00133111"
                    ixy="0.00040056"
                    ixz="-0.00000811"
                    iyy="0.00203159"
                    iyz="0.00000230"
                    izz="0.00178062"/>
        </inertial>
        <visual>
            <origin
                    xyz="0 0 0"
                    rpy="0 0 0"/>
            <geometry>
                <mesh
                        filename="package://legged_rl_description/meshes/biped/abad_left_link.STL"/>
            </geometry>
            <material
                    name="">
                <color
                        rgba="0.79216 0.81961 0.93333 1"/>
            </material>
        </visual>
        <!--    <collision>-->
        <!--      <origin-->
        <!--        xyz="0 0 0"-->
        <!--        rpy="0 0 0" />-->
        <!--      <geometry>-->
        <!--        <mesh-->
        <!--          filename="package://legged_rl_description/meshes/biped/abad_left_link.STL" />-->
        <!--      </geometry>-->
        <!--    </collision>-->
    </link>
    <joint
            name="abad_L_Joint"
            type="revolute">
        <origin
                xyz="0.0142 0.095 -0.08176"
                rpy="0 0 0"/>
        <parent
                link="base"/>
        <child
                link="abad_L_Link"/>
        <axis
                xyz="1 0 0"/>
        <limit
                lower="-0.69813"
                upper="1.39626"
                effort="20"
                velocity="52.4"/>
    </joint>
    <link
            name="hip_L_Link">
        <inertial>
            <origin
                    xyz="-0.03047400 -0.05446455 -0.03920244"
                    rpy="0 0 0"/>
            <mass
                    value="1.73405445"/>
            <inertia
                    ixx="0.01148168"
                    ixy="0.00124007"
                    ixz="-0.00625658"
                    iyy="0.01576674"
                    iyz="0.00159648"
                    izz="0.00699881"/>
        </inertial>
        <visual>
            <origin
                    xyz="0 0 0"
                    rpy="0 0 0"/>
            <geometry>
                <mesh
                        filename="package://legged_rl_description/meshes/biped/hip_left_link.STL"/>
            </geometry>
            <material
                    name="">
                <color
                        rgba="0.79216 0.81961 0.93333 1"/>
            </material>
        </visual>
        <!--    <collision>-->
        <!--      <origin-->
        <!--        xyz="0 0 0"-->
        <!--        rpy="0 0 0" />-->
        <!--      <geometry>-->
        <!--        <mesh-->
        <!--          filename="package://legged_rl_description/meshes/biped/hip_left_link.STL" />-->
        <!--      </geometry>-->
        <!--    </collision>-->
    </link>
    <joint
            name="hip_L_Joint"
            type="revolute">
        <origin
                xyz="-0.0802 0.031 0"
                rpy="0 0 0"/>
        <parent
                link="abad_L_Link"/>
        <child
                link="hip_L_Link"/>
        <axis
                xyz="0 -1 0"/>
        <limit
                lower="-1.012"
                upper="1.012"
                effort="30"
                velocity="52.4"/>
    </joint>
    <link
            name="knee_L_Link">
        <inertial>
            <origin
                    xyz="0.05607029 -0.00007153 -0.08804698"
                    rpy="0 0 0"/>
            <mass
                    value="0.25930748"/>
            <inertia
                    ixx="0.00222212"
                    ixy="-0.00000163"
                    ixz="0.00139314"
                    iyy="0.00312233"
                    iyz="0.00000239"
                    izz="0.00093345"/>
        </inertial>
        <visual>
            <origin
                    xyz="0 0 0"
                    rpy="0 0 0"/>
            <geometry>
                <mesh
                        filename="package://legged_rl_description/meshes/biped/knee_left_link.STL"/>
            </geometry>
            <material
                    name="">
                <color
                        rgba="0.79216 0.81961 0.93333 1"/>
            </material>
        </visual>
        <collision>
            <origin
                    xyz="0 0 0"
                    rpy="0 0 0"/>
            <geometry>
                <mesh
                        filename="package://legged_rl_description/meshes/biped/knee_left_link.STL"/>
            </geometry>
        </collision>
    </link>
    <joint
            name="knee_L_Joint"
            type="revolute">
        <origin
                xyz="-0.15 -0.021 -0.25981"
                rpy="0 0 0"/>
        <parent
                link="hip_L_Link"/>
        <child
                link="knee_L_Link"/>
        <axis
                xyz="0 -1 0"/>
        <limit
                lower="-1.04719"
                upper="1.39626"
                effort="30"
                velocity="52.4"/>
    </joint>
    <link
            name="foot_L_Link">
        <inertial>
            <origin
                    xyz="-0.00245810 0.00000000 0.03706242"
                    rpy="0 0 0"/>
            <mass
                    value="0.14047647"/>
            <inertia
                    ixx="0.00007326"
                    ixy="0.0"
                    ixz="0.00000519"
                    iyy="0.00007655"
                    iyz="0.0"
                    izz="0.00005623"/>
        </inertial>
        <visual>
            <origin
                    xyz="0 0 0"
                    rpy="0 0 0"/>
            <geometry>
                <mesh
                        filename="package://legged_rl_description/meshes/biped/foot_left_link.STL"/>
            </geometry>
            <material
                    name="">
                <color
                        rgba="0.79216 0.81961 0.93333 1"/>
            </material>
        </visual>
        <collision>
            <origin
                    xyz="0 0 0"
                    rpy="0 0 0"/>
            <geometry>
                <mesh
                        filename="package://legged_rl_description/meshes/biped/foot_left_link.STL"/>
            </geometry>
        </collision>
    </link>
    <joint
            name="foot_L_Joint"
            type="fixed"
            dont_collapse="true">
        <origin
                xyz="0.15 0 -0.29066"
                rpy="0 0 0"/>
        <parent
                link="knee_L_Link"/>
        <child
                link="foot_L_Link"/>
        <axis
                xyz="0 0 0"/>
    </joint>
    <gazebo reference="foot_L_Joint">
        <disableFixedJointLumping>true</disableFixedJointLumping>
    </gazebo>
    <gazebo reference="hip_L_Link">
        <mu1>0.2</mu1>
        <mu2>0.2</mu2>
        <material>Gazebo/DarkGrey</material>
    </gazebo>
    <gazebo reference="knee_L_Link">
        <mu1>0.2</mu1>
        <mu2>0.2</mu2>
        <self_collide>0</self_collide>
        <material>Gazebo/DarkGrey</material>
        <kp value="1000000.0"/>
        <kd value="100.0"/>
    </gazebo>
    <gazebo reference="foot_L_Link">
        <mu1>0.6</mu1>
        <mu2>0.6</mu2>
        <self_collide>1</self_collide>
        <material>Gazebo/DarkGrey</material>
        <kp value="1000000.0"/>
        <kd value="100.0"/>
    </gazebo>
    <transmission name="abad_L_Joint_tran">
        <type>transmission_interface/SimpleTransmission</type>
        <joint name="abad_L_Joint">
            <hardwareInterface>hardware_interface/EffortJointInterface</hardwareInterface>
        </joint>
        <actuator name="abad_L_Joint_motor">
            <hardwareInterface>hardware_interface/EffortJointInterface</hardwareInterface>
            <mechanicalReduction>1</mechanicalReduction>
        </actuator>
    </transmission>
    <transmission name="hip_L_Joint_tran">
        <type>transmission_interface/SimpleTransmission</type>
        <joint name="hip_L_Joint">
            <hardwareInterface>hardware_interface/EffortJointInterface</hardwareInterface>
        </joint>
        <actuator name="hip_L_Joint_motor">
            <hardwareInterface>hardware_interface/EffortJointInterface</hardwareInterface>
            <mechanicalReduction>1</mechanicalReduction>
        </actuator>
    </transmission>
    <transmission name="knee_L_Joint_tran">
        <type>transmission_interface/SimpleTransmission</type>
        <joint name="knee_L_Joint">
            <hardwareInterface>hardware_interface/EffortJointInterface</hardwareInterface>
        </joint>
        <actuator name="knee_L_Joint_motor">
            <hardwareInterface>hardware_interface/EffortJointInterface</hardwareInterface>
            <mechanicalReduction>1</mechanicalReduction>
        </actuator>
    </transmission>

    <link
            name="abad_R_Link">
        <inertial>
            <origin
                    xyz="-0.07010283 -0.04726372 0.00010253"
                    rpy="0 0 0"/>
            <mass
                    value="1.03648872"/>
            <inertia
                    ixx="0.00133125"
                    ixy="-0.00040058"
                    ixz="-0.00000791"
                    iyy="0.00203161"
                    iyz="-0.00000238"
                    izz="0.00178049"/>
        </inertial>
        <visual>
            <origin
                    xyz="0 0 0"
                    rpy="0 0 0"/>
            <geometry>
                <mesh
                        filename="package://legged_rl_description/meshes/biped/abad_right_link.STL"/>
            </geometry>
            <material
                    name="">
                <color
                        rgba="0.79216 0.81961 0.93333 1"/>
            </material>
        </visual>
        <!--    <collision>-->
        <!--      <origin-->
        <!--        xyz="0 0 0"-->
        <!--        rpy="0 0 0" />-->
        <!--      <geometry>-->
        <!--        <mesh-->
        <!--          filename="package://legged_rl_description/meshes/biped/abad_right_link.STL" />-->
        <!--      </geometry>-->
        <!--    </collision>-->
    </link>
    <joint
            name="abad_R_Joint"
            type="revolute">
        <origin
                xyz="0.0142 -0.095 -0.08176"
                rpy="0 0 0"/>
        <parent
                link="base"/>
        <child
                link="abad_R_Link"/>
        <axis
                xyz="-1 0 0"/>
        <limit
                lower="-0.69813"
                upper="1.39626"
                effort="30"
                velocity="52.4"/>
    </joint>
    <link
            name="hip_R_Link">
        <inertial>
            <origin
                    xyz="-0.03047721 0.05446458 -0.03919637"
                    rpy="0 0 0"/>
            <mass
                    value="1.73405240"/>
            <inertia
                    ixx="0.01148221"
                    ixy="-0.00123983"
                    ixz="-0.00625649"
                    iyy="0.01576712"
                    iyz="-0.00159690"
                    izz="0.00699866"/>
        </inertial>
        <visual>
            <origin
                    xyz="0 0 0"
                    rpy="0 0 0"/>
            <geometry>
                <mesh
                        filename="package://legged_rl_description/meshes/biped/hip_right_link.STL"/>
            </geometry>
            <material
                    name="">
                <color
                        rgba="1 0.98039 0.6 1"/>
            </material>
        </visual>
        <!--    <collision>-->
        <!--      <origin-->
        <!--        xyz="0 0 0"-->
        <!--        rpy="0 0 0" />-->
        <!--      <geometry>-->
        <!--        <mesh-->
        <!--          filename="package://legged_rl_description/meshes/biped/hip_right_link.STL" />-->
        <!--      </geometry>-->
        <!--    </collision>-->
    </link>
    <joint
            name="hip_R_Joint"
            type="revolute">
        <origin
                xyz="-0.0802 -0.031 0"
                rpy="0 0 0"/>
        <parent
                link="abad_R_Link"/>
        <child
                link="hip_R_Link"/>
        <axis
                xyz="0 -1 0"/>
        <limit
                lower="-1.012"
                upper="1.012"
                effort="30"
                velocity="52.4"/>
    </joint>
    <link
            name="knee_R_Link">
        <inertial>
            <origin
                    xyz="0.05607065 0.00007138 -0.08804757"
                    rpy="0 0 0"/>
            <mass
                    value="0.25930895"/>
            <inertia
                    ixx="0.00222213"
                    ixy="0.00000163"
                    ixz="0.00139315"
                    iyy="0.00312235"
                    iyz="-0.00000239"
                    izz="0.00093346"/>
        </inertial>
        <visual>
            <origin
                    xyz="0 0 0"
                    rpy="0 0 0"/>
            <geometry>
                <mesh
                        filename="package://legged_rl_description/meshes/biped/knee_right_link.STL"/>
            </geometry>
            <material
                    name="">
                <color
                        rgba="0.79216 0.81961 0.93333 1"/>
            </material>
        </visual>
        <collision>
            <origin
                    xyz="0 0 0"
                    rpy="0 0 0"/>
            <geometry>
                <mesh
                        filename="package://legged_rl_description/meshes/biped/knee_right_link.STL"/>
            </geometry>
        </collision>
    </link>
    <joint
            name="knee_R_Joint"
            type="revolute">
        <origin
                xyz="-0.15 0.021 -0.25981"
                rpy="0 0 0"/>
        <parent
                link="hip_R_Link"/>
        <child
                link="knee_R_Link"/>
        <axis
                xyz="0 1 0"/>
        <limit
                lower="-1.39626"
                upper="1.04719"
                effort="30"
                velocity="52.4"/>
    </joint>
    <link
            name="foot_R_Link">
        <inertial>
            <origin
                    xyz="-0.00245810 0.00000000 0.03706242"
                    rpy="0 0 0"/>
            <mass
                    value="0.14047647"/>
            <inertia
                    ixx="0.00007326"
                    ixy="0.0"
                    ixz="0.00000519"
                    iyy="0.00007655"
                    iyz="0.0"
                    izz="0.00005623"/>
        </inertial>
        <visual>
            <origin
                    xyz="0 0 0"
                    rpy="0 0 0"/>
            <geometry>
                <mesh
                        filename="package://legged_rl_description/meshes/biped/foot_right_link.STL"/>
            </geometry>
            <material
                    name="">
                <color
                        rgba="0.79216 0.81961 0.93333 1"/>
            </material>
        </visual>
        <collision>
            <origin
                    xyz="0 0 0"
                    rpy="0 0 0"/>
            <geometry>
                <mesh
                        filename="package://legged_rl_description/meshes/biped/foot_right_link.STL"/>
            </geometry>
        </collision>
    </link>
    <joint
            name="foot_R_Joint"
            type="fixed"
            dont_collapse="true">
        <origin
                xyz="0.15 0 -0.29066"
                rpy="0 0 0"/>
        <parent
                link="knee_R_Link"/>
        <child
                link="foot_R_Link"/>
        <axis
                xyz="0 0 0"/>
    </joint>
    <gazebo reference="foot_R_Joint">
        <disableFixedJointLumping>true</disableFixedJointLumping>
    </gazebo>
    <gazebo reference="hip_R_Link">
        <mu1>0.2</mu1>
        <mu2>0.2</mu2>
        <material>Gazebo/DarkGrey</material>
    </gazebo>
    <gazebo reference="knee_R_Link">
        <mu1>0.2</mu1>
        <mu2>0.2</mu2>
        <self_collide>0</self_collide>
        <material>Gazebo/DarkGrey</material>
        <kp value="1000000.0"/>
        <kd value="100.0"/>
    </gazebo>
    <gazebo reference="foot_R_Link">
        <mu1>0.6</mu1>
        <mu2>0.6</mu2>
        <self_collide>1</self_collide>
        <material>Gazebo/DarkGrey</material>
        <kp value="1000000.0"/>
        <kd value="100.0"/>
    </gazebo>
    <transmission name="abad_R_Joint_tran">
        <type>transmission_interface/SimpleTransmission</type>
        <joint name="abad_R_Joint">
            <hardwareInterface>hardware_interface/EffortJointInterface</hardwareInterface>
        </joint>
        <actuator name="abad_R_Joint_motor">
            <hardwareInterface>hardware_interface/EffortJointInterface</hardwareInterface>
            <mechanicalReduction>1</mechanicalReduction>
        </actuator>
    </transmission>
    <transmission name="hip_R_Joint_tran">
        <type>transmission_interface/SimpleTransmission</type>
        <joint name="hip_R_Joint">
            <hardwareInterface>hardware_interface/EffortJointInterface</hardwareInterface>
        </joint>
        <actuator name="hip_R_Joint_motor">
            <hardwareInterface>hardware_interface/EffortJointInterface</hardwareInterface>
            <mechanicalReduction>1</mechanicalReduction>
        </actuator>
    </transmission>
    <transmission name="knee_R_Joint_tran">
        <type>transmission_interface/SimpleTransmission</type>
        <joint name="knee_R_Joint">
            <hardwareInterface>hardware_interface/EffortJointInterface</hardwareInterface>
        </joint>
        <actuator name="knee_R_Joint_motor">
            <hardwareInterface>hardware_interface/EffortJointInterface</hardwareInterface>
            <mechanicalReduction>1</mechanicalReduction>
        </actuator>
    </transmission>
</robot>