<?xml version="1.0" encoding="utf-8"?>
<!-- This URDF was automatically created by SolidWorks to URDF Exporter! Originally created by Stephen Brawner (brawner@gmail.com)
     Commit Version: 1.6.0-1-g15f4949  Build Version: 1.6.7594.29634
     For more information, please see http://wiki.ros.org/sw_urdf_exporter -->
<robot name="lite3">
    <material name="black">
        <color rgba="0.0 0.0 0.0 1.0"/>
    </material>
    <material name="blue">
        <color rgba="0.0 0.0 0.8 1.0"/>
    </material>
    <material name="green">
        <color rgba="0.0 0.8 0.0 1.0"/>
    </material>
    <material name="grey">
        <color rgba="0.2 0.2 0.2 1.0"/>
    </material>
    <material name="silver">
        <color rgba="0.9137254901960784 0.9137254901960784 0.8470588235294118 1.0"/>
    </material>
    <material name="orange">
        <color rgba="1.0 0.4235294117647059 0.0392156862745098 1.0"/>
    </material>
    <material name="brown">
        <color rgba="0.8705882352941177 0.8117647058823529 0.7647058823529411 1.0"/>
    </material>
    <material name="red">
        <color rgba="0.8 0.0 0.0 1.0"/>
    </material>
    <material name="white">
        <color rgba="1.0 1.0 1.0 1.0"/>
    </material>

    <!-- ros_control plugin -->
    <gazebo>
        <plugin filename="liblegged_hw_sim.so" name="gazebo_ros_control">
            <robotNamespace>/</robotNamespace>
            <robotParam>legged_robot_description</robotParam>
            <robotSimType>legged_gazebo/LeggedHWSim</robotSimType>
        </plugin>
    </gazebo>
    <gazebo>
        <plugin filename="libgazebo_ros_p3d.so" name="p3d_base_controller">
            <alwaysOn>true</alwaysOn>
            <updateRate>1000.0</updateRate>
            <bodyName>base</bodyName>
            <topicName>ground_truth/state</topicName>
            <gaussianNoise>0</gaussianNoise>
            <frameName>world</frameName>
            <xyzOffsets>0 0 0</xyzOffsets>
            <rpyOffsets>0 0 0</rpyOffsets>
        </plugin>
    </gazebo>
    <!-- LF leg -->
    <gazebo reference="LF_hip">
        <mu1>0.2</mu1>
        <mu2>0.2</mu2>
        <material>Gazebo/DarkGrey</material>
    </gazebo>
    <gazebo reference="LF_thigh">
        <mu1>0.2</mu1>
        <mu2>0.2</mu2>
        <self_collide>0</self_collide>
        <material>Gazebo/DarkGrey</material>
        <kp value="1000000.0"/>
        <kd value="1.0"/>
    </gazebo>
    <gazebo reference="LF_calf">
        <mu1>0.2</mu1>
        <mu2>0.2</mu2>
        <self_collide>1</self_collide>
    </gazebo>
    <gazebo reference="LF_FOOT">
        <mu1>0.6</mu1>
        <mu2>0.6</mu2>
        <self_collide>1</self_collide>
        <material>Gazebo/DarkGrey</material>
        <kp value="1000000.0"/>
        <kd value="1.0"/>
    </gazebo>
    <!-- RF leg -->
    <gazebo reference="RF_hip">
        <mu1>0.2</mu1>
        <mu2>0.2</mu2>
        <material>Gazebo/DarkGrey</material>
    </gazebo>
    <gazebo reference="RF_thigh">
        <mu1>0.2</mu1>
        <mu2>0.2</mu2>
        <self_collide>0</self_collide>
        <material>Gazebo/DarkGrey</material>
        <kp value="1000000.0"/>
        <kd value="1.0"/>
    </gazebo>
    <gazebo reference="RF_calf">
        <mu1>0.2</mu1>
        <mu2>0.2</mu2>
        <self_collide>1</self_collide>
    </gazebo>
    <gazebo reference="RF_FOOT">
        <mu1>0.6</mu1>
        <mu2>0.6</mu2>
        <self_collide>1</self_collide>
        <material>Gazebo/DarkGrey</material>
        <kp value="1000000.0"/>
        <kd value="1.0"/>
    </gazebo>
    <!-- LH leg -->
    <gazebo reference="LH_hip">
        <mu1>0.2</mu1>
        <mu2>0.2</mu2>
        <material>Gazebo/DarkGrey</material>
    </gazebo>
    <gazebo reference="LH_thigh">
        <mu1>0.2</mu1>
        <mu2>0.2</mu2>
        <self_collide>0</self_collide>
        <material>Gazebo/DarkGrey</material>
        <kp value="1000000.0"/>
        <kd value="1.0"/>
    </gazebo>
    <gazebo reference="LH_calf">
        <mu1>0.2</mu1>
        <mu2>0.2</mu2>
        <self_collide>1</self_collide>
    </gazebo>
    <gazebo reference="LH_FOOT">
        <mu1>0.6</mu1>
        <mu2>0.6</mu2>
        <self_collide>1</self_collide>
        <material>Gazebo/DarkGrey</material>
        <kp value="1000000.0"/>
        <kd value="1.0"/>
    </gazebo>
    <!-- RH leg -->
    <gazebo reference="RH_hip">
        <mu1>0.2</mu1>
        <mu2>0.2</mu2>
        <material>Gazebo/DarkGrey</material>
    </gazebo>
    <gazebo reference="RH_thigh">
        <mu1>0.2</mu1>
        <mu2>0.2</mu2>
        <self_collide>0</self_collide>
        <material>Gazebo/DarkGrey</material>
        <kp value="1000000.0"/>
        <kd value="1.0"/>
    </gazebo>
    <gazebo reference="RH_calf">
        <mu1>0.2</mu1>
        <mu2>0.2</mu2>
        <self_collide>1</self_collide>
    </gazebo>
    <gazebo reference="RH_FOOT">
        <mu1>0.6</mu1>
        <mu2>0.6</mu2>
        <self_collide>1</self_collide>
        <material>Gazebo/DarkGrey</material>
        <kp value="1000000.0"/>
        <kd value="1.0"/>
    </gazebo>

    <link name="base">
        <inertial>
            <origin xyz="0.004098 -0.000663 -0.002069" rpy="0 0 0"/>
            <mass value="4.130"/>
            <inertia ixx="0.016982120" ixy="2.1294E-05" ixz="6.0763E-05" iyy="0.030466501" iyz="1.7968E-05"
                     izz="0.042609956"/>
        </inertial>
        <visual>
            <origin xyz="0 0 0" rpy="0 0 3.14159265"/>
            <geometry>
                <mesh filename="package://legged_deep_description/meshes/lite3/trunk.dae"/>
            </geometry>
        </visual>
        <collision>
            <geometry>
                <box size="0.35 0.184 0.08"/>
            </geometry>
        </collision>
    </link>
    <!-- Imu is fixed to the base link -->
    <joint name="unitree_imu_joint" type="fixed">
        <origin rpy="0. 0. 0." xyz="0. 0. 0."/>
        <parent link="base"/>
        <child link="unitree_imu"/>
    </joint>
    <!-- Imu link -->
    <link name="unitree_imu">
        <inertial>
            <mass value="0.01"/>
            <origin rpy="0 0 0" xyz="0 0 0"/>
            <inertia ixx="0.000001" ixy="0" ixz="0" iyy="0.000001" iyz="0" izz="0.000001"/>
        </inertial>
    </link>
    <gazebo reference="unitree_imu_joint">
        <disableFixedJointLumping>true</disableFixedJointLumping>
    </gazebo>

    <link name="LF_hip">
        <inertial>
            <origin
                    xyz="-0.0047 -0.0091 -0.0018"
                    rpy="0 0 0"/>
            <mass
                    value="0.428"/>
            <inertia ixx="0.00014538" ixy="8.1579E-07" ixz="-1.264E-05" iyy="0.00024024" iyz="1.3443E-06"
                     izz="0.00013038"/>
        </inertial>
        <visual>
            <origin xyz="0 0 0" rpy="0 0 0"/>
            <geometry>
                <mesh filename="package://legged_deep_description/meshes/lite3/FL_HIP.dae"/>
            </geometry>
        </visual>
        <!--    <collision>-->
        <!--      <origin rpy="1.5707963267948966 0 0" xyz="0 0 0"/>-->
        <!--      <geometry>-->
        <!--        <cylinder length="0.0418" radius="0.046"/>-->
        <!--      </geometry>-->
        <!--    </collision>-->
    </link>
    <joint name="LF_HAA" type="revolute">
        <origin xyz="0.1745 0.062 0" rpy="0 0 0"/>
        <parent link="base"/>
        <child link="LF_hip"/>
        <axis xyz="1 0 0"/>
        <limit lower="-0.523" upper="0.523" effort="40" velocity="30"/>
    </joint>
    <link name="LF_thigh">
        <inertial>
            <origin
                    xyz="-0.00523 -0.0216 -0.0273"
                    rpy="0 0 0"/>
            <mass
                    value="0.61"/>
            <inertia ixx="0.001" ixy="-2.5E-06" ixz="-1.12E-04" iyy="0.00116" iyz="3.75E-07" izz="2.68E-04"/>
        </inertial>
        <visual>
            <origin xyz="0 0 0" rpy="0 0 0"/>
            <geometry>
                <mesh filename="package://legged_deep_description/meshes/lite3/L_THIGH.dae"/>
            </geometry>
        </visual>
        <collision>
            <origin xyz="0 0 -0.08"/>
            <geometry>
                <box size="0.03 0.03 0.16"/>
            </geometry>
        </collision>
    </link>
    <joint name="LF_HFE" type="revolute">
        <origin xyz="0 0.0985 0" rpy="0 0 0"/>
        <parent link="LF_hip"/>
        <child link="LF_thigh"/>
        <axis xyz="0 1 0"/>
        <limit lower="-0.314" upper="2.67" effort="40" velocity="30"/>
    </joint>
    <link name="LF_calf">
        <inertial>
            <origin
                    xyz="0.00585 -8.732E-07 -0.12"
                    rpy="0 0 0"/>
            <mass
                    value="0.115"/>
            <inertia ixx="6.68E-04" ixy="-1.24E-08" ixz="6.91E-06" iyy="6.86E-04" iyz="5.65E-09" izz="3.155E-05"/>
        </inertial>
        <visual>
            <origin xyz="0 0 0" rpy="0 0 0"/>
            <geometry>
                <mesh filename="package://legged_deep_description/meshes/lite3/SHANK.dae"/>
            </geometry>
        </visual>
        <collision>
            <origin rpy="0 0 0" xyz="0 0 -0.09"/>
            <geometry>
                <box size="0.02 0.02 0.18"/>
            </geometry>
        </collision>
    </link>
    <joint name="LF_KFE" type="revolute">
        <origin xyz="0 0 -0.20" rpy="0 0 0"/>
        <parent link="LF_thigh"/>
        <child link="LF_calf"/>
        <axis xyz="0 1 0"/>
        <limit lower="-2.792" upper="-0.524" effort="65" velocity="20"/>
    </joint>
    <link name="LF_FOOT">
        <visual>
            <origin rpy="0 0 0" xyz="0 0 0"/>
            <geometry>
                <sphere radius="0.0165"/>
            </geometry>
            <material name="orange"/>
        </visual>
        <collision>
            <origin rpy="0 0 0" xyz="0 0 0"/>
            <geometry>
                <sphere radius="0.02"/>
            </geometry>
        </collision>
        <inertial>
            <mass value="0.06"/>
            <inertia ixx="1.6853999999999998e-05" ixy="0.0" ixz="0.0" iyy="1.6853999999999998e-05" iyz="0.0"
                     izz="1.6853999999999998e-05"/>
        </inertial>
    </link>
    <joint name="LF_foot_fixed" type="fixed">
        <origin xyz="0 0 -0.21" rpy="0 0 0"/>
        <parent link="LF_calf"/>
        <child link="LF_FOOT"/>
    </joint>
    <gazebo reference="LF_foot_fixed">
        <disableFixedJointLumping>true</disableFixedJointLumping>
    </gazebo>

    <link name="RF_hip">
        <inertial>
            <origin
                    xyz="-0.0047 0.0091 -0.0018"
                    rpy="0 0 0"/>
            <mass
                    value="0.428"/>
            <inertia ixx="0.00014538" ixy="-8.1551E-07" ixz="-1.2639E-05" iyy="0.00024024" iyz="-1.3441E-06"
                     izz="0.00013038"/>
        </inertial>
        <visual>
            <origin xyz="0 0 0" rpy="0 0 0"/>
            <geometry>
                <mesh filename="package://legged_deep_description/meshes/lite3/FR_HIP.dae"/>
            </geometry>
        </visual>
        <!--    <collision>-->
        <!--      <origin rpy="1.5707963267948966 0 0" xyz="0 0 0"/>-->
        <!--      <geometry>-->
        <!--        <cylinder length="0.0418" radius="0.046"/>-->
        <!--      </geometry>-->
        <!--    </collision>-->
    </link>
    <joint name="RF_HAA" type="revolute">
        <origin xyz="0.1745 -0.062 0" rpy="0 0 0"/>
        <parent link="base"/>
        <child link="RF_hip"/>
        <axis xyz="1 0 0"/>
        <limit lower="-0.523" upper="0.523" effort="40" velocity="30"/>
    </joint>
    <link name="RF_thigh">
        <inertial>
            <origin
                    xyz="-0.00523 0.0216 -0.0273"
                    rpy="0 0 0"/>
            <mass
                    value="0.61"/>
            <inertia ixx="0.001" ixy="2.5E-06" ixz="-1.12E-04" iyy="0.00116" iyz="-3.75E-07" izz="2.68E-04"/>
        </inertial>
        <visual>
            <origin xyz="0 0 0" rpy="0 0 0"/>
            <geometry>
                <mesh filename="package://legged_deep_description/meshes/lite3/R_THIGH.dae"/>
            </geometry>
        </visual>
        <collision>
            <origin xyz="0 0 -0.08"/>
            <geometry>
                <box size="0.03 0.03 0.16"/>
            </geometry>
        </collision>
    </link>
    <joint name="RF_HFE" type="revolute">
        <origin xyz="0 -0.0985 0" rpy="0 0 0"/>
        <parent link="RF_hip"/>
        <child link="RF_thigh"/>
        <axis xyz="0 1 0"/>
        <limit lower="-0.314" upper="2.67" effort="40" velocity="30"/>
    </joint>
    <link name="RF_calf">
        <inertial>
            <origin
                    xyz="0.00585 -8.732E-07 -0.12"
                    rpy="0 0 0"/>
            <mass
                    value="0.115"/>
            <inertia ixx="6.68E-04" ixy="-1.24E-08" ixz="6.91E-06" iyy="6.86E-04" iyz="5.65E-09" izz="3.155E-05"/>
        </inertial>
        <visual>
            <origin xyz="0 0 0" rpy="0 0 0"/>
            <geometry>
                <mesh filename="package://legged_deep_description/meshes/lite3/SHANK.dae"/>
            </geometry>
        </visual>
        <collision>
            <origin rpy="0 0 0" xyz="0 0 -0.09"/>
            <geometry>
                <box size="0.02 0.02 0.18"/>
            </geometry>
        </collision>
    </link>
    <joint name="RF_KFE" type="revolute">
        <origin xyz="0 0 -0.20" rpy="0 0 0"/>
        <parent link="RF_thigh"/>
        <child link="RF_calf"/>
        <axis xyz="0 1 0"/>
        <!--    <limit lower="0" upper="0" effort="80.0" velocity="20.0" />-->
        <limit lower="-2.792" upper="-0.524" effort="65" velocity="20"/>
    </joint>
    <link name="RF_FOOT">
        <visual>
            <origin rpy="0 0 0" xyz="0 0 0"/>
            <geometry>
                <sphere radius="0.0165"/>
            </geometry>
            <material name="orange"/>
        </visual>
        <collision>
            <origin rpy="0 0 0" xyz="0 0 0"/>
            <geometry>
                <sphere radius="0.02"/>
            </geometry>
        </collision>
        <inertial>
            <mass value="0.06"/>
            <inertia ixx="1.6853999999999998e-05" ixy="0.0" ixz="0.0" iyy="1.6853999999999998e-05" iyz="0.0"
                     izz="1.6853999999999998e-05"/>
        </inertial>
    </link>
    <joint name="RF_foot_fixed" type="fixed">
        <origin xyz="0 0 -0.21" rpy="0 0 0"/>
        <parent link="RF_calf"/>
        <child link="RF_FOOT"/>
        <axis xyz="0 1 0"/>
    </joint>
    <gazebo reference="RF_foot_fixed">
        <disableFixedJointLumping>true</disableFixedJointLumping>
    </gazebo>

    <link name="LH_hip">
        <inertial>
            <origin
                    xyz="0.0047 -0.0091 -0.0018"
                    rpy="0 0 0"/>
            <mass
                    value="0.428"/>
            <inertia ixx="0.00014538" ixy="-8.1585E-07" ixz="1.2639E-05" iyy="0.00024024" iyz="1.3444E-06"
                     izz="0.00013038"/>
        </inertial>
        <visual>
            <origin xyz="0 0 0" rpy="0 0 0"/>
            <geometry>
                <mesh filename="package://legged_deep_description/meshes/lite3/HL_HIP.dae"/>
            </geometry>
        </visual>
        <!--    <collision>-->
        <!--      <origin rpy="1.5707963267948966 0 0" xyz="0 0 0"/>-->
        <!--      <geometry>-->
        <!--        <cylinder length="0.0418" radius="0.046"/>-->
        <!--      </geometry>-->
        <!--    </collision>-->
    </link>
    <joint name="LH_HAA" type="revolute">
        <origin xyz="-0.1745 0.062 0" rpy="0 0 0"/>
        <parent link="base"/>
        <child link="LH_hip"/>
        <axis xyz="1 0 0"/>
        <limit lower="-0.523" upper="0.523" effort="40" velocity="30"/>
    </joint>
    <link name="LH_thigh">
        <inertial>
            <origin
                    xyz="-0.00523 -0.0216 -0.0273"
                    rpy="0 0 0"/>
            <mass
                    value="0.61"/>
            <inertia ixx="0.001" ixy="-2.5E-06" ixz="-1.12E-04" iyy="0.00116" iyz="3.75E-07" izz="2.68E-04"/>
        </inertial>
        <visual>
            <origin xyz="0 0 0" rpy="0 0 0"/>
            <geometry>
                <mesh filename="package://legged_deep_description/meshes/lite3/L_THIGH.dae"/>
            </geometry>
        </visual>
        <collision>
            <origin xyz="0 0 -0.08"/>
            <geometry>
                <box size="0.03 0.03 0.16"/>
            </geometry>
        </collision>
    </link>
    <joint name="LH_HFE" type="revolute">
        <origin xyz="0 0.0985 0" rpy="0 0 0"/>
        <parent link="LH_hip"/>
        <child link="LH_thigh"/>
        <axis xyz="0 1 0"/>
        <limit lower="-0.314" upper="2.67" effort="40" velocity="30"/>
    </joint>
    <link name="LH_calf">
        <inertial>
            <origin
                    xyz="0.00585 -8.732E-07 -0.12"
                    rpy="0 0 0"/>
            <mass
                    value="0.115"/>
            <inertia ixx="6.68E-04" ixy="-1.24E-08" ixz="6.91E-06" iyy="6.86E-04" iyz="5.65E-09" izz="3.155E-05"/>
        </inertial>
        <visual>
            <origin xyz="0 0 0" rpy="0 0 0"/>
            <geometry>
                <mesh filename="package://legged_deep_description/meshes/lite3/SHANK.dae"/>
            </geometry>
        </visual>
        <collision>
            <origin rpy="0 0 0" xyz="0 0 -0.09"/>
            <geometry>
                <box size="0.02 0.02 0.18"/>
            </geometry>
        </collision>
    </link>
    <joint name="LH_KFE" type="revolute">
        <origin xyz="0 0 -0.20" rpy="0 0 0"/>
        <parent link="LH_thigh"/>
        <child link="LH_calf"/>
        <axis xyz="0 1 0"/>
        <limit lower="-2.792" upper="-0.524" effort="65" velocity="20"/>
    </joint>
    <link name="LH_FOOT">
        <visual>
            <origin rpy="0 0 0" xyz="0 0 0"/>
            <geometry>
                <sphere radius="0.0165"/>
            </geometry>
            <material name="orange"/>
        </visual>
        <collision>
            <origin rpy="0 0 0" xyz="0 0 0"/>
            <geometry>
                <sphere radius="0.02"/>
            </geometry>
        </collision>
        <inertial>
            <mass value="0.06"/>
            <inertia ixx="1.6853999999999998e-05" ixy="0.0" ixz="0.0" iyy="1.6853999999999998e-05" iyz="0.0"
                     izz="1.6853999999999998e-05"/>
        </inertial>
    </link>
    <joint name="LH_foot_fixed" type="fixed">
        <origin xyz="0 0 -0.21" rpy="0 0 0"/>
        <parent link="LH_calf"/>
        <child link="LH_FOOT"/>
        <axis xyz="0 1 0"/>
    </joint>
    <gazebo reference="LH_foot_fixed">
        <disableFixedJointLumping>true</disableFixedJointLumping>
    </gazebo>

    <link name="RH_hip">
        <inertial>
            <origin
                    xyz="0.0047 0.0091 -0.0018"
                    rpy="0 0 0"/>
            <mass
                    value="0.428"/>
            <inertia ixx="0.00014538" ixy="8.1545E-07" ixz="1.2639E-05" iyy="0.00024024" iyz="-1.344E-06"
                     izz="0.00013038"/>
        </inertial>
        <visual>
            <origin xyz="0 0 0" rpy="0 0 0"/>
            <geometry>
                <mesh filename="package://legged_deep_description/meshes/lite3/HR_HIP.dae"/>
            </geometry>
        </visual>
        <!--    <collision>-->
        <!--      <origin rpy="1.5707963267948966 0 0" xyz="0 0 0"/>-->
        <!--      <geometry>-->
        <!--        <cylinder length="0.0418" radius="0.046"/>-->
        <!--      </geometry>-->
        <!--    </collision>-->
    </link>
    <joint name="RH_HAA" type="revolute">
        <origin xyz="-0.1745 -0.062 0" rpy="0 0 0"/>
        <parent link="base"/>
        <child link="RH_hip"/>
        <axis xyz="1 0 0"/>
        <limit lower="-0.523" upper="0.523" effort="40" velocity="30"/>
    </joint>
    <link name="RH_thigh">
        <inertial>
            <origin
                    xyz="-0.00523 0.0216 -0.0273"
                    rpy="0 0 0"/>
            <mass
                    value="0.61"/>
            <inertia ixx="0.001" ixy="2.5E-06" ixz="-1.12E-04" iyy="0.00116" iyz="-3.75E-07" izz="2.68E-04"/>
        </inertial>
        <visual>
            <origin xyz="0 0 0" rpy="0 0 0"/>
            <geometry>
                <mesh filename="package://legged_deep_description/meshes/lite3/R_THIGH.dae"/>
            </geometry>
        </visual>
        <collision>
            <origin xyz="0 0 -0.08"/>
            <geometry>
                <box size="0.03 0.03 0.16"/>
            </geometry>
        </collision>
    </link>
    <joint name="RH_HFE" type="revolute">
        <origin xyz="0 -0.0985 0" rpy="0 0 0"/>
        <parent link="RH_hip"/>
        <child link="RH_thigh"/>
        <axis xyz="0 1 0"/>
        <limit lower="-0.314" upper="2.67" effort="40" velocity="30"/>
    </joint>
    <link name="RH_calf">
        <inertial>
            <origin
                    xyz="0.00585 -8.732E-07 -0.12"
                    rpy="0 0 0"/>
            <mass
                    value="0.115"/>
            <inertia ixx="6.68E-04" ixy="-1.24E-08" ixz="6.91E-06" iyy="6.86E-04" iyz="5.65E-09" izz="3.155E-05"/>
        </inertial>
        <visual>
            <origin xyz="0 0 0" rpy="0 0 0"/>
            <geometry>
                <mesh filename="package://legged_deep_description/meshes/lite3/SHANK.dae"/>
            </geometry>
        </visual>
        <collision>
            <origin rpy="0 0 0" xyz="0 0 -0.09"/>
            <geometry>
                <box size="0.02 0.02 0.18"/>
            </geometry>
        </collision>
    </link>
    <joint name="RH_KFE" type="revolute">
        <origin xyz="0 0 -0.20" rpy="0 0 0"/>
        <parent link="RH_thigh"/>
        <child link="RH_calf"/>
        <axis xyz="0 1 0"/>
        <limit lower="-2.792" upper="-0.524" effort="65" velocity="20"/>
    </joint>
    <link name="RH_FOOT">
        <visual>
            <origin rpy="0 0 0" xyz="0 0 0"/>
            <geometry>
                <sphere radius="0.0165"/>
            </geometry>
            <material name="orange"/>
        </visual>
        <collision>
            <origin rpy="0 0 0" xyz="0 0 0"/>
            <geometry>
                <sphere radius="0.02"/>
            </geometry>
        </collision>
        <inertial>
            <mass value="0.06"/>
            <inertia ixx="1.6853999999999998e-05" ixy="0.0" ixz="0.0" iyy="1.6853999999999998e-05" iyz="0.0"
                     izz="1.6853999999999998e-05"/>
        </inertial>
    </link>
    <joint name="RH_foot_fixed" type="fixed">
        <origin xyz="0 0 -0.21" rpy="0 0 0"/>
        <parent link="RH_calf"/>
        <child link="RH_FOOT"/>
        <axis xyz="0 1 0"/>
    </joint>
    <gazebo reference="RH_foot_fixed">
        <disableFixedJointLumping>true</disableFixedJointLumping>
    </gazebo>

    <gazebo reference="LH_foot_fixed">
        <disableFixedJointLumping>true</disableFixedJointLumping>
    </gazebo>

    <transmission name="RF_HAA_tran">
        <type>transmission_interface/SimpleTransmission</type>
        <joint name="RF_HAA">
            <hardwareInterface>hardware_interface/EffortJointInterface</hardwareInterface>
        </joint>
        <actuator name="RF_HAA_motor">
            <hardwareInterface>hardware_interface/EffortJointInterface</hardwareInterface>
            <mechanicalReduction>1</mechanicalReduction>
        </actuator>
    </transmission>
    <transmission name="RF_HFE_tran">
        <type>transmission_interface/SimpleTransmission</type>
        <joint name="RF_HFE">
            <hardwareInterface>hardware_interface/EffortJointInterface</hardwareInterface>
        </joint>
        <actuator name="RF_HFE_motor">
            <hardwareInterface>hardware_interface/EffortJointInterface</hardwareInterface>
            <mechanicalReduction>1</mechanicalReduction>
        </actuator>
    </transmission>
    <transmission name="RF_KFE_tran">
        <type>transmission_interface/SimpleTransmission</type>
        <joint name="RF_KFE">
            <hardwareInterface>hardware_interface/EffortJointInterface</hardwareInterface>
        </joint>
        <actuator name="RF_KFE_motor">
            <hardwareInterface>hardware_interface/EffortJointInterface</hardwareInterface>
            <mechanicalReduction>1</mechanicalReduction>
        </actuator>
    </transmission>

    <transmission name="LF_HAA_tran">
        <type>transmission_interface/SimpleTransmission</type>
        <joint name="LF_HAA">
            <hardwareInterface>hardware_interface/EffortJointInterface</hardwareInterface>
        </joint>
        <actuator name="LF_HAA_motor">
            <hardwareInterface>hardware_interface/EffortJointInterface</hardwareInterface>
            <mechanicalReduction>1</mechanicalReduction>
        </actuator>
    </transmission>
    <transmission name="LF_HFE_tran">
        <type>transmission_interface/SimpleTransmission</type>
        <joint name="LF_HFE">
            <hardwareInterface>hardware_interface/EffortJointInterface</hardwareInterface>
        </joint>
        <actuator name="LF_HFE_motor">
            <hardwareInterface>hardware_interface/EffortJointInterface</hardwareInterface>
            <mechanicalReduction>1</mechanicalReduction>
        </actuator>
    </transmission>
    <transmission name="LF_KFE_tran">
        <type>transmission_interface/SimpleTransmission</type>
        <joint name="LF_KFE">
            <hardwareInterface>hardware_interface/EffortJointInterface</hardwareInterface>
        </joint>
        <actuator name="LF_KFE_motor">
            <hardwareInterface>hardware_interface/EffortJointInterface</hardwareInterface>
            <mechanicalReduction>1</mechanicalReduction>
        </actuator>
    </transmission>

    <transmission name="RH_HAA_tran">
        <type>transmission_interface/SimpleTransmission</type>
        <joint name="RH_HAA">
            <hardwareInterface>hardware_interface/EffortJointInterface</hardwareInterface>
        </joint>
        <actuator name="RH_HAA_motor">
            <hardwareInterface>hardware_interface/EffortJointInterface</hardwareInterface>
            <mechanicalReduction>1</mechanicalReduction>
        </actuator>
    </transmission>
    <transmission name="RH_HFE_tran">
        <type>transmission_interface/SimpleTransmission</type>
        <joint name="RH_HFE">
            <hardwareInterface>hardware_interface/EffortJointInterface</hardwareInterface>
        </joint>
        <actuator name="RH_HFE_motor">
            <hardwareInterface>hardware_interface/EffortJointInterface</hardwareInterface>
            <mechanicalReduction>1</mechanicalReduction>
        </actuator>
    </transmission>
    <transmission name="RH_KFE_tran">
        <type>transmission_interface/SimpleTransmission</type>
        <joint name="RH_KFE">
            <hardwareInterface>hardware_interface/EffortJointInterface</hardwareInterface>
        </joint>
        <actuator name="RH_KFE_motor">
            <hardwareInterface>hardware_interface/EffortJointInterface</hardwareInterface>
            <mechanicalReduction>1</mechanicalReduction>
        </actuator>
    </transmission>

    <transmission name="LH_HAA_tran">
        <type>transmission_interface/SimpleTransmission</type>
        <joint name="LH_HAA">
            <hardwareInterface>hardware_interface/EffortJointInterface</hardwareInterface>
        </joint>
        <actuator name="LH_HAA_motor">
            <hardwareInterface>hardware_interface/EffortJointInterface</hardwareInterface>
            <mechanicalReduction>1</mechanicalReduction>
        </actuator>
    </transmission>
    <transmission name="LH_HFE_tran">
        <type>transmission_interface/SimpleTransmission</type>
        <joint name="LH_HFE">
            <hardwareInterface>hardware_interface/EffortJointInterface</hardwareInterface>
        </joint>
        <actuator name="LH_HFE_motor">
            <hardwareInterface>hardware_interface/EffortJointInterface</hardwareInterface>
            <mechanicalReduction>1</mechanicalReduction>
        </actuator>
    </transmission>
    <transmission name="LH_KFE_tran">
        <type>transmission_interface/SimpleTransmission</type>
        <joint name="LH_KFE">
            <hardwareInterface>hardware_interface/EffortJointInterface</hardwareInterface>
        </joint>
        <actuator name="LH_KFE_motor">
            <hardwareInterface>hardware_interface/EffortJointInterface</hardwareInterface>
            <mechanicalReduction>1</mechanicalReduction>
        </actuator>
    </transmission>

</robot>